Workbook

Sheet Cover
B1: PARAG MILK FOODS
B2: #VALUE!
B4: 3-STATEMENT FINANCIAL MODEL & DCF VALUATION
B6: DATE PREPARED: | C6: =DATE(2026,4,15) -> 46127 | F6: LAST UPDATED: | I6: =NOW() -> 46131.594
B7: PREPARED BY: AKASHDEEP MUKHERJEE
B9: TABLE OF CONTENTS | E9: VALUATION SUMMARY
B10: 1. CHECKS | E10: CURRENT MARKET PRICE | H10: {=_FV(B2,"Price")} -> 222.66
B12: 2. ASSUMPTIONS & DRIVERS | E12: IMPLIED SHARE PRICE (DCF) | H12: =DCF!C37 -> 220.95735
B14: 3. INCOME STATEMENT | E14: IMPLIED SHARE PRICE (COMPS) | H14: =Comps!C22 -> 407.24966
B16: 4. BALANCE SHEET | E16: IMPLIED UPSIDE/ (DOWNSIDE) (AS PER IMPLIED SHARE PRICE (COMPS)) | H16: =(H14/H10)-1 -> 0.82902031
B18: 5. CASH FLOW STATEMENT | E18: IMPLIED UPSIDE/ (DOWNSIDE) (AS PER IMPLIED SHARE PRICE (DCF)) | H18: =DCF!G37 -> -0.0076468775
B20: 6. DCF VALUATION & SENSITIVITY ANALYSIS | E20: IMPLIED SHARE PRICE (EMM) | H20: =DCF!H25 -> 329.74287
B22: 7. COMPARABLE COMPANY ANALYSIS | E22: IMPLIED UPSIDE/ (DOWNSIDE) (AS PER IMPLIED SHARE PRICE (EMM)) | H22: =(H20/H10)-1 -> 0.48092551

Sheet Checks
B1: MODEL COMPLETION
B2: IS THE MODEL COMPLETE ? | C2: YES | E2: HAS THE MODEL BEEN TESTED | I2: YES
B4: CHECKS
B5: MASTER MODEL STATUS | C5: =IF(COUNTIF(C9:H11,"ERROR")>0,"ERRORS DETECTED","MODEL OK") -> MODEL OK
C7: FORECASTS
B8: PARTICULARS | C8: 2026 | D8: 2027 | E8: 2028 | F8: 2029 | G8: 2030 | H8: 2031
B9: Balance Sheet Balanced | C9: =IF(ROUND(C19,2)=0,"OK","ERROR") -> OK | D9: =IF(ROUND(D19,2)=0,"OK","ERROR") -> OK | E9: =IF(ROUND(E19,2)=0,"OK","ERROR") -> OK | F9: =IF(ROUND(F19,2)=0,"OK","ERROR") -> OK | G9: =IF(ROUND(G19,2)=0,"OK","ERROR") -> OK | H9: =IF(ROUND(H19,2)=0,"OK","ERROR") -> OK
B10: Cash Flow Matched Balance Sheet | C10: =IF(ROUND(C20,2)=0,"OK","ERROR") -> OK | D10: =IF(ROUND(D20,2)=0,"OK","ERROR") -> OK | E10: =IF(ROUND(E20,2)=0,"OK","ERROR") -> OK | F10: =IF(ROUND(F20,2)=0,"OK","ERROR") -> OK | G10: =IF(ROUND(G20,2)=0,"OK","ERROR") -> OK | H10: =IF(ROUND(H20,2)=0,"OK","ERROR") -> OK
B11: Net Income Matches Cash Flow Statement | C11: =IF(ROUND(C21,2)=0,"OK","ERROR") -> OK | D11: =IF(ROUND(D21,2)=0,"OK","ERROR") -> OK | E11: =IF(ROUND(E21,2)=0,"OK","ERROR") -> OK | F11: =IF(ROUND(F21,2)=0,"OK","ERROR") -> OK | G11: =IF(ROUND(G21,2)=0,"OK","ERROR") -> OK | H11: =IF(ROUND(H21,2)=0,"OK","ERROR") -> OK
B19: Balance Sheet Check | C19: ='Balance Sheet'!H40 -> 0 | D19: ='Balance Sheet'!I40 -> 0 | E19: ='Balance Sheet'!J40 -> 0 | F19: ='Balance Sheet'!K40 -> 0 | G19: ='Balance Sheet'!L40 -> 0 | H19: ='Balance Sheet'!M40 -> 0
B20: Cash Flow Check | C20: ='Cash Flow Statement'!H21-'Balance Sheet'!H14 -> 0 | D20: ='Cash Flow Statement'!I21-'Balance Sheet'!I14 -> 0 | E20: ='Cash Flow Statement'!J21-'Balance Sheet'!J14 -> 0 | F20: ='Cash Flow Statement'!K21-'Balance Sheet'!K14 -> 0 | G20: ='Cash Flow Statement'!L21-'Balance Sheet'!L14 -> 0 | H20: ='Cash Flow Statement'!M21-'Balance Sheet'!M14 -> 0
B21: Net Income Check | C21: ='Income Statement'!H17-'Cash Flow Statement'!H6 -> 0 | D21: ='Income Statement'!I17-'Cash Flow Statement'!I6 -> 0 | E21: ='Income Statement'!J17-'Cash Flow Statement'!J6 -> 0 | F21: ='Income Statement'!K17-'Cash Flow Statement'!K6 -> 0 | G21: ='Income Statement'!L17-'Cash Flow Statement'!L6 -> 0 | H21: ='Income Statement'!M17-'Cash Flow Statement'!M6 -> 0

Sheet Assumptions
B1: ASSUMPTIONS & KEY DRIVERS
M3: ₹ million
C4: HISTORICALS | H4: FORECASTS
B5: PARTICULARS | C5: 2021 | D5: 2022 | E5: 2023 | F5: 2024 | G5: 2025 | H5: 2026 | I5: 2027 | J5: 2028 | K5: 2029 | L5: 2030 | M5: 2031
B6: REVENUE ASSUMPTIONS
B7: Revenue from Operations | C7: 18417.63 | D7: 20717.54 | E7: 28926.2 | F7: =3138.7*10 -> 31387 | G7: =3432.21*10 -> 34322.1 | H7: ='Income Statement'!H6 -> 37754.31 | I7: ='Income Statement'!I6 -> 41529.741 | J7: ='Income Statement'!J6 -> 45267.418 | K7: ='Income Statement'!K6 -> 49341.485 | L7: ='Income Statement'!L6 -> 53288.804 | M7: ='Income Statement'!M6 -> 57551.908
B8: YoY Growth Rate (%) | D8: =(D7-C7)/C7 -> 0.12487546 | E8: =(E7-D7)/D7 -> 0.39621789 | F8: =(F7-E7)/E7 -> 0.085071665 | G8: =(G7-F7)/F7 -> 0.093513238 | H8: 0.1 | I8: 0.1 | J8: 0.09 | K8: 0.09 | L8: 0.08 | M8: 0.08
B10: COST ASSUMPTIONS
B11: Cost of materials consumed | C11: 13235.23 | D11: 18498.75 | E11: 23952.35 | F11: 24252.3 | G11: 24894.7
B12: Purchases of Stock-in-trade | C12: 975.31 | D12: 82.4 | E12: 0 | F12: 0 | G12: 0
B13: Changes in inventories of finished goods, stock-in-trade and work-in-progress | C13: -591.43 | D13: 2223.95 | E13: -720.49 | F13: -550.1 | G13: 572.7
B14: Cost of Raw Materials (Cost of Materials Consumed + Purchase of Stock in Trade + Changes in Inventories) | C14: =SUM(C11:C13) -> 13619.11 | D14: =SUM(D11:D13) -> 20805.1 | E14: =SUM(E11:E13) -> 23231.86 | F14: =SUM(F11:F13) -> 23702.2 | G14: =SUM(G11:G13) -> 25467.4 | H14: ='Income Statement'!H7 -> 28315.733 | I14: ='Income Statement'!I7 -> 30732.008 | J14: ='Income Statement'!J7 -> 33497.889 | K14: ='Income Statement'!K7 -> 36019.284 | L14: ='Income Statement'!L7 -> 38900.827 | M14: ='Income Statement'!M7 -> 41437.374
B15: Raw Material Cost (%) (Cost of Raw Materials/Revenue) | C15: =C14/C7 -> 0.73946051 | D15: =D14/D7 -> 1.0042264 | E15: =E14/E7 -> 0.80314248 | F15: =F14/F7 -> 0.75515978 | G15: =G14/G7 -> 0.74201171 | H15: 0.75 | I15: 0.74 | J15: 0.74 | K15: 0.73 | L15: 0.73 | M15: 0.72
B17: Employee Benefits Expenses | C17: 781.97 | D17: 836.63 | E17: 980.56 | F17: 1221.3 | G17: 1499.5 | H17: ='Income Statement'!H9 -> 1510.1724 | I17: ='Income Statement'!I9 -> 1661.1896 | J17: ='Income Statement'!J9 -> 1810.6967 | K17: ='Income Statement'!K9 -> 1973.6594 | L17: ='Income Statement'!L9 -> 2131.5522 | M17: ='Income Statement'!M9 -> 2302.0763
B18: Employee Cost (%) (Employee Benefits Expenses/Revenue) | C18: =C17/C7 -> 0.042457689 | D18: =D17/D7 -> 0.04038269 | E18: =E17/E7 -> 0.03389868 | F18: =F17/F7 -> 0.038911014 | G18: =G17/G7 -> 0.043689052 | H18: 0.04 | I18: 0.04 | J18: 0.04 | K18: 0.04 | L18: 0.04 | M18: 0.04
B20: Other Expenses | C20: 2800.37 | D20: 3459.72 | E20: 3530.42 | F20: 4458.5 | G20: 4828.4 | H20: ='Income Statement'!H10 -> 5285.6034 | I20: ='Income Statement'!I10 -> 5814.1637 | J20: ='Income Statement'!J10 -> 6337.4385 | K20: ='Income Statement'!K10 -> 6907.8079 | L20: ='Income Statement'!L10 -> 7460.4326 | M20: ='Income Statement'!M10 -> 8057.2672
B21: Other Expenses (%) (Other Expenses/Revenue) | C21: =C20/C7 -> 0.15204834 | D21: =D20/D7 -> 0.16699473 | E21: =E20/E7 -> 0.12204921 | F21: =F20/F7 -> 0.14204926 | G21: =G20/G7 -> 0.14067904 | H21: 0.14 | I21: 0.14 | J21: 0.14 | K21: 0.14 | L21: 0.14 | M21: 0.14
B23: DEPRECIATION ASSUMPTIONS
B24: Depreciation & Amortization Expenses | C24: 486.29 | D24: 537.44 | E24: 572.75 | F24: 602.5 | G24: 672.2 | H24: ='Income Statement'!H12 -> 755.0862 | I24: ='Income Statement'!I12 -> 830.59482 | J24: ='Income Statement'!J12 -> 905.34835 | K24: ='Income Statement'!K12 -> 986.82971 | L24: ='Income Statement'!L12 -> 1065.7761 | M24: ='Income Statement'!M12 -> 1151.0382
B25: D&A as % of Revenue | C25: =C24/C7 -> 0.026403506 | D25: =D24/D7 -> 0.025941304 | E25: =E24/E7 -> 0.019800389 | F25: =F24/F7 -> 0.019195845 | G25: =G24/G7 -> 0.019585049 | H25: 0.02 | I25: 0.02 | J25: 0.02 | K25: 0.02 | L25: 0.02 | M25: 0.02
B27: INTEREST ASSUMPTIONS
B28: Finance Cost | C28: 457.74 | D28: 509.59 | E28: 551.56 | F28: 794 | G28: 931.2 | H28: =H32*H33 -> 738.588 | I28: =I32*I33 -> 738.588 | J28: =J32*J33 -> 738.588 | K28: =K32*K33 -> 738.588 | L28: =L32*L33 -> 738.588 | M28: =M32*M33 -> 738.588
B29: Borrowings (Non-Current) | C29: 333.19 | D29: 2596.3 | E29: 2552.33 | F29: =244.44*10 -> 2444.4 | G29: =252.37*10 -> 2523.7 | H29: =G29 -> 2523.7 | I29: =H29 -> 2523.7 | J29: =I29 -> 2523.7 | K29: =J29 -> 2523.7 | L29: =K29 -> 2523.7 | M29: =L29 -> 2523.7
B30: Borrowings (Current) | C30: 3477.42 | D30: 2580.51 | E30: 3342.13 | F30: =339.17*10 -> 3391.7 | G30: =363.12*10 -> 3631.2 | H30: =G30 -> 3631.2 | I30: =H30 -> 3631.2 | J30: =I30 -> 3631.2 | K30: =J30 -> 3631.2 | L30: =K30 -> 3631.2 | M30: =L30 -> 3631.2
B31: Total Debt | C31: =C30+C29 -> 3810.61 | D31: =D30+D29 -> 5176.81 | E31: =E30+E29 -> 5894.46 | F31: =F30+F29 -> 5836.1 | G31: =G30+G29 -> 6154.9 | H31: =H30+H29 -> 6154.9 | I31: =I30+I29 -> 6154.9 | J31: =J30+J29 -> 6154.9 | ... M31: =M30+M29 -> 6154.9
B32: Average Total Debt | C32: 3810.61 | D32: =(C31+D31)/2 -> 4493.71 | E32: =(D31+E31)/2 -> 5535.635 | F32: =(E31+F31)/2 -> 5865.28 | G32: =(F31+G31)/2 -> 5995.5 | H32: =(G31+H31)/2 -> 6154.9 | I32: =(H31+I31)/2 -> 6154.9 | J32: =(I31+J31)/2 -> 6154.9 | K32: =(J31+K31)/2 -> 6154.9 | ... M32: =(L31+M31)/2 -> 6154.9
B33: Implied Rate | C33: =C28/C32 -> 0.1201225 | D33: =D28/D32 -> 0.11340073 | E33: =E28/E32 -> 0.099638072 | F33: =F28/F32 -> 0.13537291 | G33: =G28/G32 -> 0.15531649 | H33: 0.12 | I33: 0.12 | J33: 0.12 | K33: 0.12 | L33: 0.12 | M33: 0.12
B35: TAX ASSUMPTIONS
B36: Current Tax | C36: 61.12 | D36: 0 | E36: 0 | F36: 0 | G36: 0
B37: MAT (credit)/reversal | C37: 0 | D37: 0 | E37: 0 | F37: =0.82*10 -> 8.2 | G37: =-1.19*10 -> -11.9
B38: Deferred tax charge /(credit) | C38: 63.5 | D38: 69.34 | E38: -21.92 | F38: =-5.55*10 -> -55.5 | G38: =14.99*10 -> 149.9
B39: Tax adjustment in respect of ealier years | C39: 75.57 | D39: 35.07 | E39: 0 | F39: 0 | G39: 0
B40: Total Tax Expense | C40: =SUM(C36:C39) -> 200.19 | D40: =SUM(D36:D39) -> 104.41 | E40: =SUM(E36:E39) -> -21.92 | F40: =SUM(F36:F39) -> -47.3 | G40: =SUM(G36:G39) -> 138
B41: PBT | C41: ='Income Statement'!C15 -> 272.15 | D41: ='Income Statement'!D15 -> -5430.94 | E41: ='Income Statement'!E15 -> 59.05 | F41: ='Income Statement'!F15 -> 608.5 | G41: ='Income Statement'!G15 -> 923.4 | H41: ='Income Statement'!H15 -> 1149.1275 | I41: ='Income Statement'!I15 -> 1753.1965 | J41: ='Income Statement'!J15 -> 1977.4571 | ... M41: ='Income Statement'!M15 -> 3865.5647
B42: Effective Tax Rate (%) (Total Tax Expense/PBT) | C42: =C40/C41 -> 0.73558699 | D42: =D40/D41 -> -0.019225033 | E42: =E40/E41 -> -0.37121084 | F42: =F40/F41 -> -0.077732128 | G42: =G40/G41 -> 0.14944769 | H42: 0.25 | I42: 0.25 | J42: 0.25 | K42: 0.25 | L42: 0.25 | M42: 0.25
B44: WORKING CAPITAL ASSUMPTIONS
B45: Trade Recievables | C45: 1589.48 | D45: 1253.07 | E45: 1682.34 | F45: 2442.6 | G45: 2595.1 | H45: =(H7/365)*H46 -> 2896.221 | I45: =(I7/365)*I46 -> 3185.8431 | J45: =(J7/365)*J46 -> 3348.5487 | K45: =(K7/365)*K46 -> 3649.9181 | L45: =(L7/365)*L46 -> 3795.9148 | M45: =(M7/365)*M46 -> 3941.9115
B46: Recievable Days | C46: =(C45/C7)*365 -> 31.500264 | D46: =(D45/D7)*365 -> 22.076489 | E46: =(E45/E7)*365 -> 21.228302 | F46: =(F45/F7)*365 -> 28.40504 | G46: =(G45/G7)*365 -> 27.597714 | H46: 28 | I46: 28 | J46: 27 | K46: 27 | L46: 26 | M46: 25
B48: Inventories | C48: 6947.85 | D48: 4787.35 | E48: 5735.5 | F48: 6153.2 | G48: 5779.5 | H48: =(H14/365)*H49 -> 6594.0747 | I48: =(I14/365)*I49 -> 7156.7691 | J48: =(J14/365)*J49 -> 7709.1032 | K48: =(K14/365)*K49 -> 8289.3695 | L48: =(L14/365)*L49 -> 8845.9415 | M48: =(M14/365)*M49 -> 9422.7453
B49: Inventory Days | C49: =(C48/C14)*365 -> 186.20639 | D49: =(D48/D14)*365 -> 83.988193 | E49: =(E48/E14)*365 -> 90.111489 | F49: =(F48/F14)*365 -> 94.755677 | G49: =(G48/G14)*365 -> 82.832072 | H49: 85 | I49: 85 | J49: 84 | K49: 84 | L49: 83 | M49: 83
...

Sheet Income Statement
B1: INCOME STATEMENT
M2: ₹ million
C3: HISTORICALS | H3: FORECASTS
B4: PARTICULARS | C4: 2021 | D4: 2022 | E4: 2023 | F4: 2024 | G4: 2025 | H4: 2026 | I4: 2027 | J4: 2028 | K4: 2029 | L4: 2030 | M4: 2031
B6: Revenue from operations | C6: =Assumptions!C7 -> 18417.63 | D6: =Assumptions!D7 -> 20717.54 | E6: =Assumptions!E7 -> 28926.2 | F6: =Assumptions!F7 -> 31387 | G6: =Assumptions!G7 -> 34322.1 | H6: =G6*(1+Assumptions!H8) -> 37754.31 | I6: =H6*(1+Assumptions!I8) -> 41529.741 | J6: =I6*(1+Assumptions!J8) -> 45267.418 | K6: =J6*(1+Assumptions!K8) -> 49341.485 | L6: =K6*(1+Assumptions!L8) -> 53288.804 | M6: =L6*(1+Assumptions!M8) -> 57551.908
B7: Cost of Raw Materials | C7: =Assumptions!C14 -> 13619.11 | D7: =Assumptions!D14 -> 20805.1 | E7: =Assumptions!E14 -> 23231.86 | F7: =Assumptions!F14 -> 23702.2 | G7: =Assumptions!G14 -> 25467.4 | H7: =H6*Assumptions!H15 -> 28315.733 | I7: =I6*Assumptions!I15 -> 30732.008 | J7: =J6*Assumptions!J15 -> 33497.889 | K7: =K6*Assumptions!K15 -> 36019.284 | L7: =L6*Assumptions!L15 -> 38900.827 | M7: =M6*Assumptions!M15 -> 41437.374
B8: Gross Profit | C8: =C6-C7 -> 4798.52 | D8: =D6-D7 -> -87.56 | E8: =E6-E7 -> 5694.34 | F8: =F6-F7 -> 7684.8 | G8: =G6-G7 -> 8854.7 | H8: =H6-H7 -> 9438.5775 | I8: =I6-I7 -> 10797.733 | J8: =J6-J7 -> 11769.529 | ... M8: =M6-M7 -> 16114.534
B9: Employee benefits expense | C9: =Assumptions!C17 -> 781.97 | D9: =Assumptions!D17 -> 836.63 | E9: =Assumptions!E17 -> 980.56 | F9: =Assumptions!F17 -> 1221.3 | G9: =Assumptions!G17 -> 1499.5 | H9: =H6*Assumptions!H18 -> 1510.1724 | I9: =I6*Assumptions!I18 -> 1661.1896 | J9: =J6*Assumptions!J18 -> 1810.6967 | K9: =K6*Assumptions!K18 -> 1973.6594 | L9: =L6*Assumptions!L18 -> 2131.5522 | M9: =M6*Assumptions!M18 -> 2302.0763
B10: Other expenses | C10: =Assumptions!C20 -> 2800.37 | D10: =Assumptions!D20 -> 3459.72 | E10: =Assumptions!E20 -> 3530.42 | F10: =Assumptions!F20 -> 4458.5 | G10: =Assumptions!G20 -> 4828.4 | H10: =H6*Assumptions!H21 -> 5285.6034 | I10: =I6*Assumptions!I21 -> 5814.1637 | J10: =J6*Assumptions!J21 -> 6337.4385 | K10: =K6*Assumptions!K21 -> 6907.8079 | L10: =L6*Assumptions!L21 -> 7460.4326 | M10: =M6*Assumptions!M21 -> 8057.2672
B11: EBITDA | C11: =C8-(C10+C9) -> 1216.18 | D11: =D8-(D10+D9) -> -4383.91 | E11: =E8-(E10+E9) -> 1183.36 | F11: =F8-(F10+F9) -> 2005 | G11: =G8-(G10+G9) -> 2526.8 | H11: =H8-(H10+H9) -> 2642.8017 | I11: =I8-(I10+I9) -> 3322.3793 | J11: =J8-(J10+J9) -> 3621.3934 | ... M11: =M8-(M10+M9) -> 5755.1908
B12: Depreciation and amortisation expense | C12: =Assumptions!C24 -> 486.29 | D12: =Assumptions!D24 -> 537.44 | E12: =Assumptions!E24 -> 572.75 | F12: =Assumptions!F24 -> 602.5 | G12: =Assumptions!G24 -> 672.2 | H12: =H6*Assumptions!H25 -> 755.0862 | I12: =I6*Assumptions!I25 -> 830.59482 | J12: =J6*Assumptions!J25 -> 905.34835 | K12: =K6*Assumptions!K25 -> 986.82971 | L12: =L6*Assumptions!L25 -> 1065.7761 | M12: =M6*Assumptions!M25 -> 1151.0382
B13: EBIT | C13: =C11-C12 -> 729.89 | D13: =D11-D12 -> -4921.35 | E13: =E11-E12 -> 610.61 | F13: =F11-F12 -> 1402.5 | G13: =G11-G12 -> 1854.6 | H13: =H11-H12 -> 1887.7155 | I13: =I11-I12 -> 2491.7845 | J13: =J11-J12 -> 2716.0451 | ... M13: =M11-M12 -> 4604.1527
B14: Finance Cost | C14: =Assumptions!C28 -> 457.74 | D14: =Assumptions!D28 -> 509.59 | E14: =Assumptions!E28 -> 551.56 | F14: =Assumptions!F28 -> 794 | G14: =Assumptions!G28 -> 931.2 | H14: =Assumptions!H28 -> 738.588 | I14: =Assumptions!I28 -> 738.588 | J14: =Assumptions!J28 -> 738.588 | ... M14: =Assumptions!M28 -> 738.588
B15: EBT (Earnings Before Tax) | C15: =C13-C14 -> 272.15 | D15: =D13-D14 -> -5430.94 | E15: =E13-E14 -> 59.05 | F15: =F13-F14 -> 608.5 | G15: =G13-G14 -> 923.4 | H15: =H13-H14 -> 1149.1275 | I15: =I13-I14 -> 1753.1965 | J15: =J13-J14 -> 1977.4571 | ... M15: =M13-M14 -> 3865.5647
B16: Total Tax Expense | C16: =Assumptions!C40 -> 200.19 | D16: =Assumptions!D40 -> 104.41 | E16: =Assumptions!E40 -> -21.92 | F16: =Assumptions!F40 -> -47.3 | G16: =Assumptions!G40 -> 138 | H16: =H15*Assumptions!H42 -> 287.28187 | I16: =I15*Assumptions!I42 -> 438.29911 | J16: =J15*Assumptions!J42 -> 494.36427 | K16: =K15*Assumptions!K42 -> 678.82899 | L16: =L15*Assumptions!L42 -> 747.90707 | M16: =M15*Assumptions!M42 -> 966.39117
B17: Net Income | C17: =C15-C16 -> 71.96 | D17: =D15-D16 -> -5535.35 | E17: =E15-E16 -> 80.97 | F17: =F15-F16 -> 655.8 | G17: =G15-G16 -> 785.4 | H17: =H15-H16 -> 861.84562 | I17: =I15-I16 -> 1314.8973 | J17: =J15-J16 -> 1483.0928 | ... M17: =M15-M16 -> 2899.1735

Sheet Balance Sheet
B1: BALANCE SHEET
M2: ₹ million
C3: HISTORICALS | H3: FORECASTS
B4: PARTICULARS | C4: 2021 | D4: 2022 | E4: 2023 | F4: 2024 | G4: 2025 | H4: 2026 | I4: 2027 | J4: 2028 | K4: 2029 | L4: 2030 | M4: 2031
B5: ASSETS
B6: Non-Current Assets
B7: Property, Plant and Equipment | C7: 4310.61 | D7: 3932.59 | E7: 3602.83 | F7: 3552.8 | G7: 4485.5 | H7: =Assumptions!H63 -> 4863.0431 | I7: =Assumptions!I63 -> 5278.3405 | J7: =Assumptions!J63 -> 5731.0147 | K7: =Assumptions!K63 -> 6224.4295 | L7: =Assumptions!L63 -> 6757.3176 | M7: =Assumptions!M63 -> 7332.8367
B8: Other Intangible Assets | C8: 19.43 | D8: 3.88 | E8: 1.95 | F8: 9 | G8: 19.8 | H8: 19.8 | I8: 19.8 | J8: 19.8 | K8: 19.8 | L8: 19.8 | M8: 19.8
B9: Other Non-Current Assets | C9: 636.56 | D9: 932.5 | E9: 1783.54 | F9: 2302.5 | G9: 2240.9 | H9: 2240.9 | I9: 2240.9 | J9: 2240.9 | K9: 2240.9 | L9: 2240.9 | M9: 2240.9
B10: Total Non-Current Assets | C10: =SUM(C7:C9) -> 4966.6 | D10: =SUM(D7:D9) -> 4868.97 | E10: =SUM(E7:E9) -> 5388.32 | F10: =SUM(F7:F9) -> 5864.3 | G10: =SUM(G7:G9) -> 6746.2 | H10: =SUM(H7:H9) -> 7123.7431 | I10: =SUM(I7:I9) -> 7539.0405 | J10: =SUM(J7:J9) -> 7991.7147 | ... M10: =SUM(M7:M9) -> 9593.5367
B11: Current Assets
B12: Inventories | C12: =Assumptions!C48 -> 6947.85 | D12: =Assumptions!D48 -> 4787.35 | E12: =Assumptions!E48 -> 5735.5 | F12: =Assumptions!F48 -> 6153.2 | G12: =Assumptions!G48 -> 5779.5 | H12: =Assumptions!H48 -> 6594.0747 | I12: =Assumptions!I48 -> 7156.7691 | J12: =Assumptions!J48 -> 7709.1032 | ... M12: =Assumptions!M48 -> 9422.7453
B13: Trade Receivables | C13: =Assumptions!C45 -> 1589.48 | D13: =Assumptions!D45 -> 1253.07 | E13: =Assumptions!E45 -> 1682.34 | F13: =Assumptions!F45 -> 2442.6 | G13: =Assumptions!G45 -> 2595.1 | H13: =Assumptions!H45 -> 2896.221 | I13: =Assumptions!I45 -> 3185.8431 | J13: =Assumptions!J45 -> 3348.5487 | ... M13: =Assumptions!M45 -> 3941.9115
B14: Cash and Cash Equivalents | C14: 69.45 | D14: 796.73 | E14: 137.99 | F14: 105.6 | G14: 118.9 | H14: ='Cash Flow Statement'!H21 -> -431.66333 | I14: ='Cash Flow Statement'!I21 -> -159.30212 | J14: ='Cash Flow Statement'!J21 -> 321.9454 | K14: ='Cash Flow Statement'!K21 -> 1211.3436 | L14: ='Cash Flow Statement'!L21 -> 2373.5535 | M14: ='Cash Flow Statement'!M21 -> 4196.7896
B15: Other Current Assets | C15: 3251.91 | D15: 2244.15 | E15: 3731.84 | F15: 4343.2 | G15: 5086.7 | H15: 5086.7 | I15: 5086.7 | J15: 5086.7 | K15: 5086.7 | L15: 5086.7 | M15: 5086.7
B16: Total Current Assets | C16: =SUM(C12:C15) -> 11858.69 | D16: =SUM(D12:D15) -> 9081.3 | E16: =SUM(E12:E15) -> 11287.67 | F16: =SUM(F12:F15) -> 13044.6 | G16: =SUM(G12:G15) -> 13580.2 | H16: =SUM(H12:H15) -> 14145.332 | I16: =SUM(I12:I15) -> 15270.01 | J16: =SUM(J12:J15) -> 16466.297 | ... M16: =SUM(M12:M15) -> 22648.146
B17: Total Assets | C17: =C10+C16 -> 16825.29 | D17: =D10+D16 -> 13950.27 | E17: =E10+E16 -> 16675.99 | F17: =F10+F16 -> 18908.9 | G17: =G10+G16 -> 20326.4 | H17: =H10+H16 -> 21269.076 | I17: =I10+I16 -> 22809.051 | J17: =J10+J16 -> 24458.012 | ... M17: =M10+M16 -> 32241.683
B19: EQUITY AND LIABILITIES
B20: Equity
B21: Equity Share Capital | C21: 839.39 | D21: 952 | E21: 1172 | F21: =119.2*10 -> 1192 | G21: =119.2*10 -> 1192 | H21: =119.2*10 -> 1192 | I21: =119.2*10 -> 1192 | J21: =119.2*10 -> 1192 | K21: =119.2*10 -> 1192 | L21: =119.2*10 -> 1192 | M21: =119.2*10 -> 1192
B22: Other Equity | C22: 8442.03 | D22: 4588.29 | E22: 6907.09 | F22: =792.91*10 -> 7929.1 | G22: =904.21*10 -> 9042.1 | H22: =G22+'Income Statement'!H17 -> 9903.9456 | I22: =H22+'Income Statement'!I17 -> 11218.843 | J22: =I22+'Income Statement'!J17 -> 12701.936 | K22: =J22+'Income Statement'!K17 -> 14738.423 | L22: =K22+'Income Statement'!L17 -> 16982.144 | M22: =L22+'Income Statement'!M17 -> 19881.317
B23: Total Equity | C23: =C22+C21 -> 9281.42 | D23: =D22+D21 -> 5540.29 | E23: =E22+E21 -> 8079.09 | F23: =F22+F21 -> 9121.1 | G23: =G22+G21 -> 10234.1 | H23: =H22+H21 -> 11095.946 | I23: =I22+I21 -> 12410.843 | J23: =J22+J21 -> 13893.936 | ... M23: =M22+M21 -> 21073.317
B25: LIABILITIES
B26: Non-Current Liabilities
B27: Borrowings | C27: =Assumptions!C29 -> 333.19 | D27: =Assumptions!D29 -> 2596.3 | E27: =Assumptions!E29 -> 2552.33 | F27: =Assumptions!F29 -> 2444.4 | G27: =Assumptions!G29 -> 2523.7 | H27: =Assumptions!H29 -> 2523.7 | I27: =Assumptions!I29 -> 2523.7 | J27: =Assumptions!J29 -> 2523.7 | ... M27: =Assumptions!M29 -> 2523.7
B28: Other Non-Current Liabilities | C28: 127.92 | D28: 180.57 | E28: 160.25 | F28: 335.9 | G28: 461.2 | H28: 461.2 | I28: 461.2 | J28: 461.2 | K28: 461.2 | L28: 461.2 | M28: 461.2
B29: Other Liabilities (Provisions & Tax) | C29: =Assumptions!C54 -> 231.19 | D29: =Assumptions!D54 -> 436.47 | E29: =Assumptions!E54 -> 599.39 | F29: =Assumptions!F54 -> 485 | G29: =Assumptions!G54 -> 303.1 | H29: =Assumptions!H54 -> 303.1 | I29: =Assumptions!I54 -> 303.1 | J29: =Assumptions!J54 -> 303.1 | ... M29: =Assumptions!M54 -> 303.1
B30: Total Non-Current Liabilities | C30: =SUM(C27:C29) -> 692.3 | D30: =SUM(D27:D29) -> 3213.34 | E30: =SUM(E27:E29) -> 3311.97 | F30: =SUM(F27:F29) -> 3265.3 | G30: =SUM(G27:G29) -> 3288 | H30: =SUM(H27:H29) -> 3288 | I30: =SUM(I27:I29) -> 3288 | J30: =SUM(J27:J29) -> 3288 | ... M30: =SUM(M27:M29) -> 3288
B31: Current liabilities
B32: Borrowings | C32: =Assumptions!C30 -> 3477.42 | D32: =Assumptions!D30 -> 2580.51 | E32: =Assumptions!E30 -> 3342.13 | F32: =Assumptions!F30 -> 3391.7 | G32: =Assumptions!G30 -> 3631.2 | H32: =Assumptions!H30 -> 3631.2 | I32: =Assumptions!I30 -> 3631.2 | J32: =Assumptions!J30 -> 3631.2 | ... M32: =Assumptions!M30 -> 3631.2
B33: Trade Payables | C33: =Assumptions!C51 -> 3041.3 | D33: =Assumptions!D51 -> 2258.59 | E33: =Assumptions!E51 -> 1525.84 | F33: =Assumptions!F51 -> 2494.4 | G33: =Assumptions!G51 -> 2556.8 | H33: =Assumptions!H51 -> 2637.6299 | I33: =Assumptions!I51 -> 2862.7076 | J33: =Assumptions!J51 -> 3028.5763 | ... M33: =Assumptions!M51 -> 3632.8657
B34: Other Current Liabilities | C34: 332.85 | D34: 357.54 | E34: 416.96 | F34: 636.4 | G34: 616.3 | H34: 616.3 | I34: 616.3 | J34: 616.3 | K34: 616.3 | L34: 616.3 | M34: 616.3
B35: Total Current liabilities | C35: =SUM(C32:C34) -> 6851.57 | D35: =SUM(D32:D34) -> 5196.64 | E35: =SUM(E32:E34) -> 5284.93 | F35: =SUM(F32:F34) -> 6522.5 | G35: =SUM(G32:G34) -> 6804.3 | H35: =SUM(H32:H34) -> 6885.1299 | I35: =SUM(I32:I34) -> 7110.2076 | J35: =SUM(J32:J34) -> 7276.0763 | ... M35: =SUM(M32:M34) -> 7880.3657
B36: Total Liabilities | C36: =C35+C30 -> 7543.87 | D36: =D35+D30 -> 8409.98 | E36: =E35+E30 -> 8596.9 | F36: =F35+F30 -> 9787.8 | G36: =G35+G30 -> 10092.3 | H36: =H35+H30 -> 10173.13 | I36: =I35+I30 -> 10398.208 | J36: =J35+J30 -> 10564.076 | ... M36: =M35+M30 -> 11168.366
B37: Total Equity and Liabilities | C37: =C36+C23 -> 16825.29 | D37: =D36+D23 -> 13950.27 | E37: =E36+E23 -> 16675.99 | F37: =F36+F23 -> 18908.9 | G37: =G36+G23 -> 20326.4 | H37: =H36+H23 -> 21269.076 | I37: =I36+I23 -> 22809.051 | J37: =J36+J23 -> 24458.012 | ... M37: =M36+M23 -> 32241.683
B39: BALANCE SHEET CHECK | C39: =IF(C17=C37,"BALANCED","ERROR") -> BALANCED | D39: =IF(D17=D37,"BALANCED","ERROR") -> BALANCED | E39: =IF(E17=E37,"BALANCED","ERROR") -> BALANCED | F39: =IF(F17=F37,"BALANCED","ERROR") -> BALANCED | G39: =IF(G17=G37,"BALANCED","ERROR") -> BALANCED | H39: =IF(H17=H37,"BALANCED","ERROR") -> BALANCED | I39: =IF(I17=I37,"BALANCED","ERROR") -> BALANCED | J39: =IF(J17=J37,"BALANCED","ERROR") -> BALANCED | ... M39: =IF(M17=M37,"BALANCED","ERROR") -> BALANCED
B40: Error Margin (If any) | C40: =C17-C37 -> 0 | D40: =D17-D37 -> 0 | E40: =E17-E37 -> 0 | F40: =F17-F37 -> 0 | G40: =G17-G37 -> 0 | H40: =H17-H37 -> 0 | I40: =I17-I37 -> 0 | J40: =J17-J37 -> 0 | ... M40: =M17-M37 -> 0

Sheet Cash Flow Statement
B1: CASH FLOW STATEMENT
M2: ₹ million
C3: HISTORICALS | H3: FORECASTS
B4: PARTICULARS | C4: 2021 | D4: 2022 | E4: 2023 | F4: 2024 | G4: 2025 | H4: 2026 | I4: 2027 | J4: 2028 | K4: 2029 | L4: 2030 | M4: 2031
B5: (A) CASH FLOW FROM OPERATIONS (CFO)
B6: Net Income | C6: ='Income Statement'!C17 -> 71.96 | D6: ='Income Statement'!D17 -> -5535.35 | E6: ='Income Statement'!E17 -> 80.97 | F6: ='Income Statement'!F17 -> 655.8 | G6: ='Income Statement'!G17 -> 785.4 | H6: ='Income Statement'!H17 -> 861.84562 | I6: ='Income Statement'!I17 -> 1314.8973 | J6: ='Income Statement'!J17 -> 1483.0928 | ... M6: ='Income Statement'!M17 -> 2899.1735
B7: (+) Depreciation & Amortization | C7: ='Income Statement'!C12 -> 486.29 | D7: ='Income Statement'!D12 -> 537.44 | E7: ='Income Statement'!E12 -> 572.75 | F7: ='Income Statement'!F12 -> 602.5 | G7: ='Income Statement'!G12 -> 672.2 | H7: ='Income Statement'!H12 -> 755.0862 | I7: ='Income Statement'!I12 -> 830.59482 | J7: ='Income Statement'!J12 -> 905.34835 | ... M7: ='Income Statement'!M12 -> 1151.0382
B8: Changes in Working Capital:
B9: (Increase) / Decrease in Trade Receivables | D9: =Assumptions!C45-Assumptions!D45 -> 336.41 | E9: =Assumptions!D45-Assumptions!E45 -> -429.27 | F9: =Assumptions!E45-Assumptions!F45 -> -760.26 | G9: =Assumptions!F45-Assumptions!G45 -> -152.5 | H9: =Assumptions!G45-Assumptions!H45 -> -301.12104 | I9: =Assumptions!H45-Assumptions!I45 -> -289.6221 | J9: =Assumptions!I45-Assumptions!J45 -> -162.70556 | K9: =Assumptions!J45-Assumptions!K45 -> -301.36938 | ... M9: =Assumptions!L45-Assumptions!M45 -> -145.99672
B10: (Increase) / Decrease in Inventories | D10: =Assumptions!C48-Assumptions!D48 -> 2160.5 | E10: =Assumptions!D48-Assumptions!E48 -> -948.15 | F10: =Assumptions!E48-Assumptions!F48 -> -417.7 | G10: =Assumptions!F48-Assumptions!G48 -> 373.7 | H10: =Assumptions!G48-Assumptions!H48 -> -814.57469 | I10: =Assumptions!H48-Assumptions!I48 -> -562.69437 | J10: =Assumptions!I48-Assumptions!J48 -> -552.33418 | K10: =Assumptions!J48-Assumptions!K48 -> -580.26628 | ... M10: =Assumptions!L48-Assumptions!M48 -> -576.80386
B11: Increase / (Decrease) in Trade Payables | D11: =Assumptions!D51-Assumptions!C51 -> -782.71 | E11: =Assumptions!E51-Assumptions!D51 -> -732.75 | F11: =Assumptions!F51-Assumptions!E51 -> 968.56 | G11: =Assumptions!G51-Assumptions!F51 -> 62.4 | H11: =Assumptions!H51-Assumptions!G51 -> 80.829877 | I11: =Assumptions!I51-Assumptions!H51 -> 225.07775 | J11: =Assumptions!J51-Assumptions!I51 -> 165.86865 | K11: =Assumptions!K51-Assumptions!J51 -> 227.96175 | ... M11: =Assumptions!M51-Assumptions!L51 -> 222.38221
B12: Net Cash from Operations | C12: =SUM(C6:C11) -> 558.25 | D12: =SUM(D6:D11) -> -3283.71 | E12: =SUM(E6:E11) -> -1456.45 | F12: =SUM(F6:F11) -> 1048.9 | G12: =SUM(G6:G11) -> 1741.2 | H12: =SUM(H6:H11) -> 582.06597 | I12: =SUM(I6:I11) -> 1518.2534 | J12: =SUM(J6:J11) -> 1839.2701 | ... M12: =SUM(M6:M11) -> 3549.7933
B13: (B) CASH FLOW FROM INVESTING (CFI)
B14: Capital Expenditures (Net PPE Movement) | C14: =-Assumptions!C57 -> -434.7 | D14: =-Assumptions!D57 -> -355.65 | E14: =-Assumptions!E57 -> -866.53 | F14: =-Assumptions!F57 -> -611.85 | G14: =-Assumptions!G57 -> -1238.5 | H14: =-Assumptions!H57 -> -1132.6293 | I14: =-Assumptions!I57 -> -1245.8922 | J14: =-Assumptions!J57 -> -1358.0225 | ... M14: =-Assumptions!M57 -> -1726.5573
B15: Net Cash from Investing | C15: =C14 -> -434.7 | D15: =D14 -> -355.65 | E15: =E14 -> -866.53 | F15: =F14 -> -611.85 | G15: =G14 -> -1238.5 | H15: =H14 -> -1132.6293 | I15: =I14 -> -1245.8922 | J15: =J14 -> -1358.0225 | ... M15: =M14 -> -1726.5573
B16: (C) CASH FLOW FROM FINANCING (CFF)
B17: Net Borrowings | D17: =Assumptions!D31-Assumptions!C31 -> 1366.2 | E17: =Assumptions!E31-Assumptions!D31 -> 717.65 | F17: =Assumptions!F31-Assumptions!E31 -> -58.36 | G17: =Assumptions!G31-Assumptions!F31 -> 318.8 | H17: =Assumptions!H31-Assumptions!G31 -> 0 | I17: =Assumptions!I31-Assumptions!H31 -> 0 | J17: =Assumptions!J31-Assumptions!I31 -> 0 | K17: =Assumptions!K31-Assumptions!J31 -> 0 | ... M17: =Assumptions!M31-Assumptions!L31 -> 0
B18: Net Cash from Financing | C18: =C17 -> 0 | D18: =D17 -> 1366.2 | E18: =E17 -> 717.65 | F18: =F17 -> -58.36 | G18: =G17 -> 318.8 | H18: =H17 -> 0 | I18: =I17 -> 0 | J18: =J17 -> 0 | ... M18: =M17 -> 0
B19: Net Change in Cash (A+B+C) | C19: =C12+C15+C18 -> 123.55 | D19: =D12+D15+D18 -> -2273.16 | E19: =E12+E15+E18 -> -1605.33 | F19: =F12+F15+F18 -> 378.69 | G19: =G12+G15+G18 -> 821.5 | H19: =H12+H15+H18 -> -550.56333 | I19: =I12+I15+I18 -> 272.36121 | J19: =J12+J15+J18 -> 481.24753 | ... M19: =M12+M15+M18 -> 1823.2361
B20: Beginning Cash Balance | C20: ='Balance Sheet'!C14 -> 69.45 | D20: ='Balance Sheet'!D14 -> 796.73 | E20: ='Balance Sheet'!E14 -> 137.99 | F20: ='Balance Sheet'!F14 -> 105.6 | G20: ='Balance Sheet'!G14 -> 118.9 | H20: ='Balance Sheet'!G14 -> 118.9 | I20: =H21 -> -431.66333 | J20: =I21 -> -159.30212 | K20: =J21 -> 321.9454 | L20: =K21 -> 1211.3436 | M20: =L21 -> 2373.5535
B21: Ending Cash Balance | C21: =C19+C20 -> 193 | D21: =D19+D20 -> -1476.43 | E21: =E19+E20 -> -1467.34 | F21: =F19+F20 -> 484.29 | G21: =G19+G20 -> 940.4 | H21: =H19+H20 -> -431.66333 | I21: =I19+I20 -> -159.30212 | J21: =J19+J20 -> 321.9454 | ... M21: =M19+M20 -> 4196.7896

Sheet DCF
B1: DISCOUNTED CASH FLOW VALUATION
M2: ₹ million
C3: HISTORICALS | H3: FORECASTS
B4: PARTICULARS | C4: 2021 | D4: 2022 | E4: 2023 | F4: 2024 | G4: 2025 | H4: 2026 | I4: 2027 | J4: 2028 | K4: 2029 | L4: 2030 | M4: 2031
B5: EBIT (Operating Profit) | H5: ='Income Statement'!H13 -> 1887.7155 | I5: ='Income Statement'!I13 -> 2491.7845 | J5: ='Income Statement'!J13 -> 2716.0451 | K5: ='Income Statement'!K13 -> 3453.904 | L5: ='Income Statement'!L13 -> 3730.2163 | M5: ='Income Statement'!M13 -> 4604.1527
B6: Less: Taxes on EBIT | H6: =H5*Assumptions!H42 -> 471.92887 | I6: =I5*Assumptions!I42 -> 622.94611 | J6: =J5*Assumptions!J42 -> 679.01127 | K6: =K5*Assumptions!K42 -> 863.47599 | L6: =L5*Assumptions!L42 -> 932.55407 | M6: =M5*Assumptions!M42 -> 1151.0382
B7: NOPAT (Net Operating Profit After Tax) | H7: =H5-H6 -> 1415.7866 | I7: =I5-I6 -> 1868.8383 | J7: =J5-J6 -> 2037.0338 | K7: =K5-K6 -> 2590.428 | L7: =L5-L6 -> 2797.6622 | M7: =M5-M6 -> 3453.1145
B8: (+) Depreciation & Amortization | H8: ='Income Statement'!H12 -> 755.0862 | I8: ='Income Statement'!I12 -> 830.59482 | J8: ='Income Statement'!J12 -> 905.34835 | K8: ='Income Statement'!K12 -> 986.82971 | L8: ='Income Statement'!L12 -> 1065.7761 | M8: ='Income Statement'!M12 -> 1151.0382
B9: (-) Capital Expenditures (CAPEX) | H9: =-'Cash Flow Statement'!H14 -> 1132.6293 | I9: =-'Cash Flow Statement'!I14 -> 1245.8922 | J9: =-'Cash Flow Statement'!J14 -> 1358.0225 | K9: =-'Cash Flow Statement'!K14 -> 1480.2446 | L9: =-'Cash Flow Statement'!L14 -> 1598.6641 | M9: =-'Cash Flow Statement'!M14 -> 1726.5573
B10: (+/-) Changes in Working Capital | H10: =SUM('Cash Flow Statement'!H9:H11) -> -1034.8659 | I10: =SUM('Cash Flow Statement'!I9:I11) -> -627.23873 | J10: =SUM('Cash Flow Statement'!J9:J11) -> -549.17109 | K10: =SUM('Cash Flow Statement'!K9:K11) -> -653.67391 | L10: =SUM('Cash Flow Statement'!L9:L11) -> -548.62324 | M10: =SUM('Cash Flow Statement'!M9:M11) -> -500.41837
B11: Unlevered Free Cash Flow (UFCF) | H11: =H7+H8-H9-H10 -> 2073.1094 | I11: =I7+I8-I9-I10 -> 2080.7797 | J11: =J7+J8-J9-J10 -> 2133.5307 | K11: =K7+K8-K9-K10 -> 2750.687 | L11: =L7+L8-L9-L10 -> 2813.3974 | M11: =M7+M8-M9-M10 -> 3378.0138
B12: Discount Period | H12: 0.5 | I12: =H12+1 -> 1.5 | J12: =I12+1 -> 2.5 | K12: =J12+1 -> 3.5 | L12: =K12+1 -> 4.5 | M12: =L12+1 -> 5.5
B13: Discount Factor | H13: =(1+$C$25)^H12 -> 1.0637669 | I13: =(1+$C$25)^I12 -> 1.2037586 | J13: =(1+$C$25)^J12 -> 1.3621732 | K13: =(1+$C$25)^K12 -> 1.5414352 | L13: =(1+$C$25)^L12 -> 1.7442881 | M13: =(1+$C$25)^M12 -> 1.9738364
B14: Present Value (PV) of UFCF | H14: =H11/H13 -> 1948.838 | I14: =I11/I13 -> 1728.5689 | J14: =J11/J13 -> 1566.2697 | K14: =K11/K13 -> 1784.4973 | L14: =L11/L13 -> 1612.9201 | M14: =M11/M13 -> 1711.395
B16: Risk Free Rate | C16: 0.07 | E16: EXIT MULTIPLE METHOD VALUATION
B17: Equity Risk Premium | C17: 0.06 | E17: Assumed Exit EV/EBITDA Multiple | H17: 12
B18: Beta | C18: 1.2 | E18: FY31 EBITDA | H18: ='Income Statement'!M11 -> 5755.1908
B19: Cost of Equity (Ke) | C19: =(C16)+(C18*C17) -> 0.142 | E19: Terminal Value (Exit Multiple) | H19: =H17*'Income Statement'!M11 -> 69062.29
B20: Pre-Tax Cost of Debt | C20: =Assumptions!H33 -> 0.12 | E20: PV of Terminal Value (Exit Multiple) | H20: =H19/M13 -> 34988.862
B21: Tax Rate | C21: =Assumptions!H42 -> 0.25 | E21: Enterprise Value (EMM) | H21: =C27+H20 -> 45341.351
B22: After-Tax Cost of Debt (Kd) | C22: =C20*(1-C21) -> 0.09 | E22: Less: Total Debt | H22: =Assumptions!M31 -> 6154.9
B23: Weight of Equity | C23: 0.8 | E23: Add: Cash and Cash Equivalents | H23: ='Balance Sheet'!G14 -> 118.9
B24: Weight of Debt | C24: 0.2 | E24: Implied Equity Value (EMM) | H24: =H21-H22+H23 -> 39305.351
B25: WACC | C25: =(C19*C23)+(C22*C24) -> 0.1316 | E25: Implied Share Price (EMM) | H25: =H24/C36 -> 329.74287
B27: Sum of PV of UCFC | C27: =SUM(H14:M14) -> 10352.489
B28: Terminal Growth Rate | C28: 0.05
B29: Terminal Value (TV) | C29: =M11*(1+C28)/(C25-C28) -> 43467.089
B30: Implied Exit EV/EBITDA | C30: =C29/('Income Statement'!M13+Assumptions!M24) -> 7.5526756
B31: PV of Terminal Value (TV) | C31: =C29/M13 -> 22021.627
B32: Enterprise Value (EV) | C32: =C27+C31 -> 32374.116
B33: Less: Total Debt | C33: =Assumptions!G31 -> 6154.9
B34: Add: Cash and Cash Equivalents | C34: ='Balance Sheet'!G14 -> 118.9
B35: Implied Equity Value | C35: =C32-C33+C34 -> 26338.116
B36: Outstanding Shares (in millions) | C36: 119.2
B37: Implied Share Price | C37: =C35/C36 -> 220.95735 | D37: Current Market Price | E37: =Cover!H10 -> 222.66 | F37: Upside / (Downside) vs CMP | G37: =(C37/E37)-1 -> -0.0076468775
B39: SENSITIVITY TABLE
C40: =C37 -> 220.95735 | D40: 0.03 | E40: 0.04 | F40: 0.05 | G40: 0.06 | H40: 0.07
C41: 0.11 | D41: 246.84133 | E41: 278.48185 | F41: 320.66923 | G41: 379.73155 | H41: 468.32503
C42: 0.12 | D42: 212.78689 | E42: 236.42276 | F42: 266.81173 | G42: 307.33036 | H42: 364.05645
C43: 0.136 | D43: 171.79385 | E43: 187.48322 | F43: 206.82128 | G43: 231.24831 | H43: 263.07747
...

Sheet Comps
B1: COMPARABLE COMPANY ANALYSIS
B2: COMPANY NAME | C2: MARKET DATA | F2: CAPITAL STRUCTURE | G2: ENTERPRICE VALUE BRIDGE | H2: OPERATING DATA LTM | J2: TRADING MULTIPLES | L2: EQUITY MULTIPLES
C4: Share Price | D4: Shares Outstanding | E4: Market Capitalization | F4: Net Debt (Total Debt minus Cash) | G4: Enterprise Value (EV) | H4: LTM Revenue (Last Twelve Months) | I4: EBITDA | J4: EV/EBITDA LTM | K4: EV/REVENUE | L4: P / E Multiple (Price to Earnings) | M4: EPS
B7: Hatsun Agro | C7: 935 | D7: 222.72 | E7: =C7*D7 -> 208243.2 | F7: 16300 | G7: =E7+F7 -> 224543.2 | H7: 95920 | I7: 10383 | J7: =G7/I7 -> 21.626043 | K7: =G7/H7 -> 2.3409425 | L7: =C7/M7 -> 54.077501 | M7: 17.29
B8: Heritage Foods | C8: 358 | D8: 92.8 | E8: =C8*D8 -> 33222.4 | F8: 1240 | G8: =E8+F8 -> 34462.4 | H8: 44170 | I8: 2095 | J8: =G8/I8 -> 16.449833 | K8: =G8/H8 -> 0.78022187 | L8: =C8/M8 -> 8.1419149 | M8: 43.97
B9: Dodla Dairy Ltd. | C9: 1058 | D9: 60.33 | E9: =C9*D9 -> 63829.14 | F9: 5140 | G9: =E9+F9 -> 68969.14 | H9: 39600 | I9: 2888 | J9: =G9/I9 -> 23.881281 | K9: =G9/H9 -> 1.7416449 | L9: =C9/M9 -> 59.74026 | M9: 17.71
B11: Average | J11: =AVERAGE(J7:J9) -> 20.652386 | K11: =AVERAGE(K7:K9) -> 1.6209364 | L11: =AVERAGE(L7:L9) -> 40.653225 | M11: =AVERAGE(M7:M9) -> 26.323333
B12: Median | J12: =MEDIAN(J7:J9) -> 21.626043 | K12: =MEDIAN(K7:K9) -> 1.7416449 | L12: =MEDIAN(L7:L9) -> 54.077501 | M12: =MEDIAN(M7:M9) -> 17.71
B15: Target EV/EBITDA Multiple | C15: =J11 -> 20.652386
B16: Parag Projected EBITDA | C16: ='Income Statement'!H11 -> 2642.8017
B17: Implied Enterprise Value | C17: =C16*C15 -> 54580.16
B18: Less: Parag Total Debt | C18: =Assumptions!G31 -> 6154.9
B19: Add: Parag Cash | C19: ='Balance Sheet'!G14 -> 118.9
B20: Implied Equity Value | C20: =C17-C18+C19 -> 48544.16
B21: Outstanding Shares | C21: 119.2
B22: Implied Share Price (Comps) | C22: =C20/C21 -> 407.24966
